Workbook

Sheet Tabela 1
A1: Metoda ekspansji | G1: Metoda Fibonacciego | K1: Metoda oparta na inperpolacji Lagrange'a
A2: Współczynnik ekspansji | B2: Lp. | C2: x(0) | D2: a | E2: b | F2: Liczba wywołań funkcji celu | G2: x* | H2: y* | I2: Liczba wywołań funkcji celu | J2: Minimum lokalne/globalne | K2: x* | L2: y* | M2: Liczba wywołań funkcji celu | N2: Minimum lokalne/globalne
A3: 1.5 | B3: 1 | C3: 35.287141 | D3: -22.377898 | E3: 9.6582349 | F3: 13 | G3: 7.7990791e-11 | H3: -7.1571657e-18 | I3: 50 | J3: lokalne | K3: 3.0719688e-10 | L3: -7.157164e-18 | M3: 5 | N3: lokalne
B4: 2 | C4: -90.654171 | D4: -32.989132 | E4: 39.092167 | F4: 14 | G4: 2.4272099e-10 | H4: -7.1571647e-18 | I4: 52 | J4: lokalne | K4: 5.532174e-13 | L4: -7.1571658e-18 | M4: 6 | N4: lokalne
B5: 3 | C5: 9.1913431 | D5: -2.1992819 | E5: 4.1288431 | F5: 9 | G5: -3.6505821e-10 | H5: -7.1571632e-18 | I5: 47 | J5: lokalne | K5: 3.2173589e-13 | L5: -7.1571658e-18 | M5: 5 | N5: lokalne
B6: 4 | C6: -51.811297 | D6: -13.367938 | E6: 34.686261 | F6: 13 | G6: -2.4835721e-10 | H6: -7.1571646e-18 | I6: 51 | J6: lokalne | K6: 3.4033827e-12 | L6: -7.1571658e-18 | M6: 6 | N6: lokalne
B7: 5 | C7: 99.080205 | D7: 41.415166 | E7: 73.451299 | F7: 13 | G7: 62.748181 | H7: -0.92114831 | I7: 50 | J7: globalne | M7: 12 | N7: brak zbieżności
B8: 6 | C8: -20.197303 | D8: -8.8066782 | E8: 5.4316031 | F8: 10 | G8: 3.7229372e-11 | H8: -7.1571658e-18 | I8: 49 | J8: lokalne | K8: 4.647871e-12 | L8: -7.1571658e-18 | M8: 5 | N8: lokalne
B9: 7 | C9: 69.024991 | D9: 61.431241 | E9: 65.649991 | F9: 8 | G9: 62.748181 | H9: -0.92114831 | I9: 46 | J9: globalne | M9: 8 | N9: brak zbieżności
B10: 8 | C10: -9.8241131 | D10: -2.2303631 | E10: 7.2618244 | F10: 9 | G10: 1.0419223e-10 | H10: -7.1571656e-18 | I10: 48 | J10: lokalne | K10: 7.238187e-13 | L10: -7.1571658e-18 | M10: 5 | N10: lokalne
B11: 9 | C11: 53.461263 | D11: 58.523763 | E11: 64.851888 | F11: 8 | G11: 62.748181 | H11: -0.92114831 | I11: 47 | J11: globalne | M11: 8 | N11: brak zbieżności
B12: 10 | C12: -69.260855 | D12: -30.817496 | E12: 17.236703 | F12: 13 | G12: -3.2278284e-10 | H12: -7.1571637e-18 | I12: 51 | J12: lokalne | K12: 2.2414795e-13 | L12: -7.1571658e-18 | M12: 7 | N12: lokalne
B13: 11 | C13: 37.027454 | D13: -20.637585 | E13: 11.398548 | F13: 13 | G13: 3.1043443e-10 | H13: -7.1571639e-18 | I13: 50 | J13: lokalne | K13: 8.574729e-10 | L13: -7.1571511e-18 | M13: 5 | N13: lokalne
B14: 12 | C14: 93.186828 | D14: 54.743468 | E14: 76.10089 | F14: 12 | G14: 62.748181 | H14: -0.92114831 | I14: 50 | J14: globalne | M14: 10 | N14: brak zbieżności
B15: 13 | C15: 31.98927 | D15: -6.4540898 | E15: 14.903332 | F15: 12 | G15: -2.0784453e-10 | H15: -7.157165e-18 | I15: 50 | J15: lokalne | K15: 2.2484824e-13 | L15: -7.1571658e-18 | M15: 6 | N15: lokalne
B16: 14 | C16: 67.493533 | D16: 59.899783 | E16: 64.118533 | F16: 8 | G16: 62.748181 | H16: -0.92114831 | I16: 46 | J16: globalne | M16: 8 | N16: brak zbieżności
B17: 15 | C17: -73.642429 | D17: 12.855129 | E17: 120.97708 | F17: 15 | G17: 62.748181 | H17: -0.92114831 | I17: 53 | J17: globalne | M17: 12 | N17: brak zbieżności
B18: 16 | C18: -70.562382 | D18: -32.119023 | E18: 15.935176 | F18: 13 | G18: 1.8465989e-10 | H18: -7.1571652e-18 | I18: 51 | J18: lokalne | K18: 2.2484695e-13 | L18: -7.1571658e-18 | M18: 7 | N18: lokalne
B19: 17 | C19: 98.910241 | D19: 41.245202 | E19: 73.281335 | F19: 13 | G19: 62.748181 | H19: -0.92114831 | I19: 50 | J19: globalne | M19: 13 | N19: brak zbieżności
B20: 18 | C20: 22.336277 | D20: -16.107082 | E20: 5.2503395 | F20: 12 | G20: -4.4219182e-11 | H20: -7.1571658e-18 | I20: 50 | J20: lokalne | K20: 8.3444308e-12 | L20: -7.1571658e-18 | M20: 5 | N20: lokalne
B21: 19 | C21: 47.994311 | D21: 59.384936 | E21: 73.623217 | F21: 10 | G21: 62.748181 | H21: -0.92114831 | I21: 49 | J21: globalne | M21: 9 | N21: brak zbieżności
B22: 20 | C22: -4.7742436 | D22: -1.3992436 | E22: 2.8195064 | F22: 7 | G22: 1.6092931e-10 | H22: -7.1571653e-18 | I22: 46 | J22: lokalne | K22: 2.7364804e-13 | L22: -7.1571658e-18 | M22: 5 | N22: lokalne
B23: 21 | C23: 92.393148 | D23: 53.949789 | E23: 75.30721 | F23: 12 | G23: 62.748181 | H23: -0.92114831 | I23: 50 | J23: globalne | M23: 10 | N23: brak zbieżności
B24: 22 | C24: 93.561656 | D24: 55.118297 | E24: 76.475719 | F24: 12 | G24: 62.748181 | H24: -0.92114831 | I24: 50 | J24: globalne | M24: 10 | N24: brak zbieżności
B25: 23 | C25: -6.0689309 | D25: -2.6939309 | E25: 1.5248191 | F25: 7 | G25: 3.9917626e-11 | H25: -7.1571658e-18 | I25: 46 | J25: lokalne | K25: 2.9646603e-13 | L25: -7.1571658e-18 | M25: 5 | N25: lokalne
B26: 24 | C26: 92.113737 | D26: 53.670378 | E26: 75.0278 | F26: 12 | G26: 62.748181 | H26: -0.92114831 | I26: 50 | J26: globalne | M26: 10 | N26: brak zbieżności
B27: 25 | C27: -13.502487 | D27: -5.9087369 | E27: 3.5834506 | F27: 9 | G27: -5.5061405e-11 | H27: -7.1571658e-18 | I27: 48 | J27: lokalne | K27: 9.8722527e-13 | L27: -7.1571658e-18 | M27: 5 | N27: lokalne
B28: 26 | C28: 60.479882 | D28: 61.979882 | E28: 63.854882 | F28: 5 | G28: 62.748181 | H28: -0.92114831 | I28: 45 | J28: globalne | M28: 7 | N28: brak zbieżności
B29: 27 | C29: -64.998034 | D29: -26.554674 | E29: 21.499525 | F29: 13 | G29: 7.2476396e-11 | H29: -7.1571657e-18 | I29: 51 | J29: lokalne | K29: -2.6488448e-12 | L29: -7.1571658e-18 | M29: 7 | N29: lokalne
B30: 28 | C30: -71.619247 | D30: -33.175888 | E30: 14.878312 | F30: 13 | G30: 2.9749951e-10 | H30: -7.1571641e-18 | I30: 51 | J30: lokalne | K30: 2.2484925e-13 | L30: -7.1571658e-18 | M30: 7 | N30: lokalne
B31: 29 | C31: 32.923093 | D31: -24.741946 | E31: 7.2941864 | F31: 13 | G31: -3.250508e-10 | H31: -7.1571637e-18 | I31: 50 | J31: lokalne | K31: 5.5974821e-11 | L31: -7.1571658e-18 | M31: 5 | N31: lokalne
B32: 30 | C32: 36.91267 | D32: -20.752369 | E32: 11.283763 | F32: 13 | G32: -1.7037618e-10 | H32: -7.1571653e-18 | I32: 50 | J32: lokalne | K32: 8.0838828e-10 | L32: -7.1571528e-18 | M32: 5 | N32: lokalne
B33: 31 | C33: 14.048304 | D33: -3.0376336 | E33: 6.4545539 | F33: 10 | G33: 2.111826e-10 | H33: -7.1571649e-18 | I33: 48 | J33: lokalne | K33: 5.0286157e-13 | L33: -7.1571658e-18 | M33: 5 | N33: lokalne
B34: 32 | C34: 72.587963 | D34: 55.502026 | E34: 64.994213 | F34: 10 | G34: 62.748181 | H34: -0.92114831 | I34: 48 | J34: globalne | M34: 8 | N34: brak zbieżności
B35: 33 | C35: -41.193679 | D35: -15.564773 | E35: 16.47136 | F35: 12 | G35: -3.5049033e-10 | H35: -7.1571634e-18 | I35: 50 | J35: lokalne | K35: 2.2484899e-13 | L35: -7.1571658e-18 | M35: 6 | N35: lokalne
B36: 34 | C36: 8.9312013 | D36: -2.4594237 | E36: 3.8687013 | F36: 9 | G36: 2.5275192e-11 | H36: -7.1571658e-18 | I36: 47 | J36: lokalne | K36: 2.9308819e-13 | L36: -7.1571658e-18 | M36: 5 | N36: lokalne
B37: 35 | C37: -22.639151 | D37: -5.5532138 | E37: 15.804208 | F37: 11 | G37: -2.2094648e-10 | H37: -7.1571649e-18 | I37: 50 | J37: lokalne | K37: 7.6245528e-12 | L37: -7.1571658e-18 | M37: 5 | N37: lokalne
B38: 36 | C38: 78.734883 | D38: 53.105976 | E38: 67.344258 | F38: 11 | G38: 62.748181 | H38: -0.92114831 | I38: 49 | J38: globalne | M38: 11 | N38: brak zbieżności
B39: 37 | C39: 58.274207 | D39: 61.649207 | E39: 65.867957 | F39: 7 | G39: 62.748181 | H39: -0.92114831 | I39: 46 | J39: globalne | M39: 7 | N39: brak zbieżności
B40: 38 | C40: 93.734329 | D40: 55.290969 | E40: 76.648391 | F40: 12 | G40: 62.748181 | H40: -0.92114831 | I40: 50 | J40: globalne | M40: 10 | N40: brak zbieżności
...

Sheet Tabela 2
A1: Współczynnik ekspansji | B1: Metoda ekspansji | D1: Rodzaj minimum | E1: Metoda Fibonacciego | I1: Metoda oparta na inperpolacji Lagrange'a
B2: b-a | C2: Liczba wywołań funkcji celu | E2: x* | F2: y* | G2: Liczba wywołań funkcji celu | H2: Liczba wystąpień | I2: x* | J2: y* | K2: Liczba wywołań funkcji celu | L2: Liczba wystąpień
A3: 1.5 | B3: =AVERAGE('Tabela 1'!$E$3:$E$102)-AVERAGE('Tabela 1'!$D$3:$D$102) -> 25.973181 | C3: =AVERAGE('Tabela 1'!$F$3:$F$102) -> 10.75 | D3: Minimum globalne | E3: =IFERROR(AVERAGEIFS('Tabela 1'!$G$3:$G$102,'Tabela 1'!$J$3:$J$102,"globalne"),"-") -> 62.748181 | F3: =IFERROR(AVERAGEIFS('Tabela 1'!$H$3:$H$102,'Tabela 1'!$J$3:$J$102,"globalne"),"-") -> -0.92114831 | G3: =IFERROR(AVERAGEIFS('Tabela 1'!$I$3:$I$102,'Tabela 1'!$J$3:$J$102,"globalne"),"-") -> 48.414634 | H3: =COUNTIF('Tabela 1'!$J$3:$J$102,"globalne") -> 41 | I3: =IFERROR(AVERAGEIFS('Tabela 1'!$K$3:$K$102,'Tabela 1'!$N$3:$N$102,"globalne"),"-") -> - | J3: =IFERROR(AVERAGEIFS('Tabela 1'!$L$3:$L$102,'Tabela 1'!$N$3:$N$102,"globalne"),"-") -> - | K3: =IFERROR(AVERAGEIFS('Tabela 1'!$M$3:$M$102,'Tabela 1'!$N$3:$N$102,"globalne"),"-") -> - | L3: =COUNTIF('Tabela 1'!$N$3:$N$102,"globalne") -> 0
D4: Minimum lokalne | E4: =IFERROR(AVERAGEIFS('Tabela 1'!$G$3:$G$102,'Tabela 1'!$J$3:$J$102,"lokalne"),"-") -> 6.0514883e-11 | F4: =IFERROR(AVERAGEIFS('Tabela 1'!$H$3:$H$102,'Tabela 1'!$J$3:$J$102,"lokalne"),"-") -> -7.1571646e-18 | G4: =IFERROR(AVERAGEIFS('Tabela 1'!$I$3:$I$102,'Tabela 1'!$J$3:$J$102,"lokalne"),"-") -> 49.457627 | H4: =COUNTIF('Tabela 1'!$J$3:$J$102,"lokalne") -> 59 | I4: =IFERROR(AVERAGEIFS('Tabela 1'!$K$3:$K$102,'Tabela 1'!$N$3:$N$102,"lokalne"),"-") -> 5.8392793e-11 | J4: =IFERROR(AVERAGEIFS('Tabela 1'!$L$3:$L$102,'Tabela 1'!$N$3:$N$102,"lokalne"),"-") -> -7.1571651e-18 | K4: =IFERROR(AVERAGEIFS('Tabela 1'!$M$3:$M$102,'Tabela 1'!$N$3:$N$102,"lokalne"),"-") -> 5.5254237 | L4: =COUNTIF('Tabela 1'!$N$3:$N$102,"lokalne") -> 59
D5: Brak zbieżności | E5: - | G5: =IFERROR(AVERAGEIFS('Tabela 1'!$I$3:$I$102,'Tabela 1'!$J$3:$J$102,"brak*"),"-") -> - | H5: =COUNTIF('Tabela 1'!$J$3:$J$102,"brak*") -> 0 | I5: - | K5: =IFERROR(AVERAGEIFS('Tabela 1'!$M$3:$M$102,'Tabela 1'!$N$3:$N$102,"brak*"),"-") -> 9.4146341 | L5: =COUNTIF('Tabela 1'!$N$3:$N$102,"brak*") -> 41
A6: 2 | B6: =AVERAGE('Tabela 1'!$E$103:$E$202)-AVERAGE('Tabela 1'!$D$103:$D$202) -> 59.3 | C6: =AVERAGE('Tabela 1'!$F$103:$F$202) -> 7.74 | D6: Minimum globalne | E6: =IFERROR(AVERAGEIFS('Tabela 1'!$G$103:$G$202,'Tabela 1'!$J$103:$J$202,"globalne"),"-") -> 62.748181 | F6: =IFERROR(AVERAGEIFS('Tabela 1'!$H$103:$H$202,'Tabela 1'!$J$103:$J$202,"globalne"),"-") -> -0.92114831 | G6: =IFERROR(AVERAGEIFS('Tabela 1'!$I$103:$I$202,'Tabela 1'!$J$103:$J$202,"globalne"),"-") -> 50.029412 | H6: =COUNTIF('Tabela 1'!$J$103:$J$202,"globalne") -> 34 | I6: =IFERROR(AVERAGEIFS('Tabela 1'!$K$103:$K$202,'Tabela 1'!$N$103:$N$202,"globalne"),"-") -> - | J6: =IFERROR(AVERAGEIFS('Tabela 1'!$L$103:$L$202,'Tabela 1'!$N$103:$N$202,"globalne"),"-") -> - | K6: =IFERROR(AVERAGEIFS('Tabela 1'!$M$103:$M$202,'Tabela 1'!$N$103:$N$202,"globalne"),"-") -> - | L6: =COUNTIF('Tabela 1'!$N$103:$N$202,"globalne") -> 0
D7: Minimum lokalne | E7: =IFERROR(AVERAGEIFS('Tabela 1'!$G$103:$G$202,'Tabela 1'!$J$103:$J$202,"lokalne"),"-") -> 0.052359963 | F7: =IFERROR(AVERAGEIFS('Tabela 1'!$H$103:$H$202,'Tabela 1'!$J$103:$J$202,"lokalne"),"-") -> 3.6188667e-06 | G7: =IFERROR(AVERAGEIFS('Tabela 1'!$I$103:$I$202,'Tabela 1'!$J$103:$J$202,"lokalne"),"-") -> 50.378788 | H7: =COUNTIF('Tabela 1'!$J$103:$J$202,"lokalne") -> 66 | I7: =IFERROR(AVERAGEIFS('Tabela 1'!$K$103:$K$202,'Tabela 1'!$N$103:$N$202,"lokalne"),"-") -> 2.6639497e-12 | J7: =IFERROR(AVERAGEIFS('Tabela 1'!$L$103:$L$202,'Tabela 1'!$N$103:$N$202,"lokalne"),"-") -> -7.1571658e-18 | K7: =IFERROR(AVERAGEIFS('Tabela 1'!$M$103:$M$202,'Tabela 1'!$N$103:$N$202,"lokalne"),"-") -> 7.1016949 | L7: =COUNTIF('Tabela 1'!$N$103:$N$202,"lokalne") -> 59
D8: Brak zbieżności | E8: - | G8: =IFERROR(AVERAGEIFS('Tabela 1'!$I$103:$I$202,'Tabela 1'!$J$103:$J$202,"brak*"),"-") -> - | H8: =COUNTIF('Tabela 1'!$J$103:$J$202,"brak*") -> 0 | I8: - | K8: =IFERROR(AVERAGEIFS('Tabela 1'!$M$103:$M$202,'Tabela 1'!$N$103:$N$202,"brak*"),"-") -> 9.0243902 | L8: =COUNTIF('Tabela 1'!$N$103:$N$202,"brak*") -> 41
A9: 2.5 | B9: =AVERAGE('Tabela 1'!$E$203:$E$302)-AVERAGE('Tabela 1'!$D$203:$D$302) -> 85.366406 | C9: =AVERAGE('Tabela 1'!$F$203:$F$302) -> 6.92 | D9: Minimum globalne | E9: =IFERROR(AVERAGEIFS('Tabela 1'!$G$203:$G$302,'Tabela 1'!$J$203:$J$302,"globalne"),"-") -> 62.748181 | F9: =IFERROR(AVERAGEIFS('Tabela 1'!$H$203:$H$302,'Tabela 1'!$J$203:$J$302,"globalne"),"-") -> -0.92114831 | G9: =IFERROR(AVERAGEIFS('Tabela 1'!$I$203:$I$302,'Tabela 1'!$J$203:$J$302,"globalne"),"-") -> 51.027027 | H9: =COUNTIF('Tabela 1'!$J$203:$J$302,"globalne") -> 37 | I9: =IFERROR(AVERAGEIFS('Tabela 1'!$K$203:$K$302,'Tabela 1'!$N$203:$N$302,"globalne"),"-") -> - | J9: =IFERROR(AVERAGEIFS('Tabela 1'!$L$203:$L$302,'Tabela 1'!$N$203:$N$302,"globalne"),"-") -> - | K9: =IFERROR(AVERAGEIFS('Tabela 1'!$M$203:$M$302,'Tabela 1'!$N$203:$N$302,"globalne"),"-") -> - | L9: =COUNTIF('Tabela 1'!$N$203:$N$302,"globalne") -> 0
D10: Minimum lokalne | E10: =IFERROR(AVERAGEIFS('Tabela 1'!$G$203:$G$302,'Tabela 1'!$J$203:$J$302,"lokalne"),"-") -> -2.0047501e-11 | F10: =IFERROR(AVERAGEIFS('Tabela 1'!$H$203:$H$302,'Tabela 1'!$J$203:$J$302,"lokalne"),"-") -> -7.1571646e-18 | G10: =IFERROR(AVERAGEIFS('Tabela 1'!$I$203:$I$302,'Tabela 1'!$J$203:$J$302,"lokalne"),"-") -> 51.206349 | H10: =COUNTIF('Tabela 1'!$J$203:$J$302,"lokalne") -> 63 | I10: =IFERROR(AVERAGEIFS('Tabela 1'!$K$203:$K$302,'Tabela 1'!$N$203:$N$302,"lokalne"),"-") -> -3.6485481e-11 | J10: =IFERROR(AVERAGEIFS('Tabela 1'!$L$203:$L$302,'Tabela 1'!$N$203:$N$302,"lokalne"),"-") -> -7.1571648e-18 | K10: =IFERROR(AVERAGEIFS('Tabela 1'!$M$203:$M$302,'Tabela 1'!$N$203:$N$302,"lokalne"),"-") -> 8.3090909 | L10: =COUNTIF('Tabela 1'!$N$203:$N$302,"lokalne") -> 55
D11: Brak zbieżności | E11: - | G11: =IFERROR(AVERAGEIFS('Tabela 1'!$I$203:$I$302,'Tabela 1'!$J$203:$J$302,"brak*"),"-") -> - | H11: =COUNTIF('Tabela 1'!$J$203:$J$302,"brak*") -> 0 | I11: - | K11: =IFERROR(AVERAGEIFS('Tabela 1'!$M$203:$M$302,'Tabela 1'!$N$203:$N$302,"brak*"),"-") -> 8.3555556 | L11: =COUNTIF('Tabela 1'!$N$203:$N$302,"brak*") -> 45
A13: Minimum globalne: x* w pobliżu 62,75 (minimum wyznaczone przeszukaniem siatki). Minimum lokalne: pozostałe zbieżne przypadki. Brak zbieżności: wyjątek w metodzie Lagrange'a (m <= 0 lub d poza przedziałem).
A14: Dla braku zbieżności podano średnią liczbę wywołań funkcji celu do momentu przerwania. Liczba wywołań Fibonacciego jest zaniżona: f(c) i f(d) liczone są jednym wywołaniem funkcji celu (wektor 2x1).

Sheet Wykres
A1: Nr iteracji | B1: b-a
B2: Metoda Fibonacciego | C2: Metoda oparta na inperpolacji Lagrange'a
A3: 1 | B3: 200 | C3: 200
A4: 2 | B4: 123.6068 | C4: 100.0001
A5: 3 | B5: 76.393202 | C5: 100
A6: 4 | B6: 47.213595 | C6: 100
A7: 5 | B7: 29.179607
A8: 6 | B8: 18.033989
A9: 7 | B9: 11.145618
A10: 8 | B10: 6.8883707
A11: 9 | B11: 4.2572473
A12: 10 | B12: 2.6311235
A13: 11 | B13: 1.6261238
A14: 12 | B14: 1.0049997
A15: 13 | B15: 0.621124
A16: 14 | B16: 0.38387575
A17: 15 | B17: 0.23724826
A18: 16 | B18: 0.14662749
... A56: 54 | B56: 1.7710758e-09

Sheet Tabela 3
A1: Metoda Fibonacciego | D1: Metoda oparta na inperpolacji Lagrange'a
A2: DA* | B2: y* | C2: Liczba wywołań funkcji celu | D2: DA* | E2: y* | F2: Liczba wywołań funkcji celu
A3: 20.224885 | B3: 1.2356467e-06 | C3: 29 | D3: 20.224876 | E3: 4.9759261e-06 | F3: 18
A5: DA* w cm². Punkt startowy x(0) = 30.1235 cm², przedział po ekspansji [13.0376; 22.5297] cm² (alpha = 1,5; d = 1 cm²).

Sheet Symulacja
A1: t | B1: VA | D1: VB | F1: TB
B2: Fibonacci | C2: Lagrange | D2: Fibonacci | E2: Lagrange | F2: Fibonacci | G2: Lagrange
A3: 0 | B3: 5 | C3: 5 | D3: 1 | E3: 1 | F3: 20 | G3: 20
A4: 1 | B4: 4.98991 | C4: 4.989907 | D4: 1.01007 | E4: 1.0100679 | F4: 20.696 | G4: 20.695996
A5: 2 | B5: 4.97982 | C5: 4.9798241 | D5: 1.02008 | E5: 1.0200757 | F5: 21.3709 | G5: 21.37085
A6: 3 | B6: 4.96975 | C6: 4.9697515 | D6: 1.03002 | E6: 1.0300238 | F6: 22.0254 | G6: 22.025432
A7: 4 | B7: 4.95969 | C7: 4.959689 | D7: 1.03991 | E7: 1.0399129 | F7: 22.6606 | G7: 22.660569
A8: 5 | B8: 4.94964 | C8: 4.9496368 | D8: 1.04974 | E8: 1.0497435 | F8: 23.277 | G8: 23.277042
A9: 6 | B9: 4.93959 | C9: 4.9395947 | D9: 1.05952 | E9: 1.059516 | F9: 23.8756 | G9: 23.875593
A10: 7 | B10: 4.92956 | C10: 4.9295629 | D10: 1.06923 | E10: 1.069231 | F10: 24.4569 | G10: 24.456926
A11: 8 | B11: 4.91954 | C11: 4.9195412 | D11: 1.07889 | E11: 1.078889 | F11: 25.0217 | G11: 25.021709
A12: 9 | B12: 4.90953 | C12: 4.9095297 | D12: 1.08849 | E12: 1.0884904 | F12: 25.5706 | G12: 25.570577
A13: 10 | B13: 4.89953 | C13: 4.8995285 | D13: 1.09804 | E13: 1.0980358 | F13: 26.1041 | G13: 26.104135
A14: 11 | B14: 4.88954 | C14: 4.8895374 | D14: 1.10753 | E14: 1.1075255 | F14: 26.623 | G14: 26.622956
... A39: 36 | B39: 4.64307 | C39: 4.6430748 | D39: 1.32791 | E39: 1.3279112 | F39: 36.0438 | G39: 36.043824
A40: 37 | B40: 4.63335 | C40: 4.6333488 | D40: 1.3361 | E40: 1.3360959 | F40: 36.3153 | G40: 36.315333 | I40: Kolumny Fibonacci: wyniki programu. Kolumny Lagrange: ten sam model (RK4, dt = 1 s) dla DA* z metody Lagrange'a.
A41: 38 | B41: 4.62363 | C41: 4.6236331 | D41: 1.34424 | E41: 1.3442351 | F41: 36.5808 | G41: 36.58083
A42: 39 | B42: 4.61393 | C42: 4.6139276 | D42: 1.35233 | E42: 1.3523291 | F42: 36.8405 | G42: 36.840486
A43: 40 | B43: 4.60423 | C43: 4.6042322 | D43: 1.36038 | E43: 1.3603782 | F43: 37.0945 | G43: 37.094467
A44: 41 | B44: 4.59455 | C44: 4.5945471 | D44: 1.36838 | E44: 1.3683827 | F44: 37.3429 | G44: 37.342932
A45: 42 | B45: 4.58487 | C45: 4.5848721 | D45: 1.37634 | E45: 1.3763428 | F45: 37.586 | G45: 37.586037
A46: 43 | B46: 4.57521 | C46: 4.5752074 | D46: 1.38426 | E46: 1.384259 | F46: 37.8239 | G46: 37.82393
A47: 44 | B47: 4.56555 | C47: 4.5655528 | D47: 1.39213 | E47: 1.3921314 | F47: 38.0568 | G47: 38.056753
A48: 45 | B48: 4.55591 | C48: 4.5559084 | D48: 1.39996 | E48: 1.3999603 | F48: 38.2847 | G48: 38.284645
A49: 46 | B49: 4.54627 | C49: 4.5462743 | D49: 1.40775 | E49: 1.407746 | F49: 38.5077 | G49: 38.50774
A50: 47 | B50: 4.53665 | C50: 4.5366503 | D50: 1.41549 | E50: 1.4154888 | F50: 38.7262 | G50: 38.726166
A51: 48 | B51: 4.52704 | C51: 4.5270365 | D51: 1.42319 | E51: 1.423189 | F51: 38.9401 | G51: 38.940048
A52: 49 | B52: 4.51743 | C52: 4.517433 | D52: 1.43085 | E52: 1.4308468 | F52: 39.1495 | G52: 39.149505
... A2003: 2000 | B2003: -1.19273e-06 | C2003: -1.1934771e-06 | D2003: 1.00402 | E2003: 1.0040183 | F2003: 20.0009 | G2003: 20.00092
